<?xml version="1.0"?>
<robot  xmlns:sensor="http://playerstage.sourceforge.net/gazebo/xmlschema/#sensor"
		xmlns:controller="http://playerstage.sourceforge.net/gazebo/xmlschema/#controller"
		xmlns:interface="http://playerstage.sourceforge.net/gazebo/xmlschema/#interface"
        xmlns:xacro="http://ros.org/wiki/xacro"
        name = "powerball">
        
 <!-- gripper -->
 <include filename="$(find wsg_50_simulation)/urdf/wsg_50.urdf.xacro" />  

<!-- powerball arm -->

<xacro:macro name="powerball_arm" params="parent name *origin">

  <joint name="${name}_0_joint" type="fixed">
    <insert_block name="origin" />
    <parent link="${parent}"/>
    <child link="${name}_0_link"/>
  </joint>
  <link name="${name}_0_link">
    <inertial>
      <origin rpy="0 0 0" xyz="0 0 0"/>
      <mass value="0.29364"/>
      <inertia ixx="0.01" ixy="0" ixz="0" iyy="0.01" iyz="0" izz="0.01"/>
    </inertial>
    <visual>
      <origin rpy="0 0 0" xyz="0 0 0"/>
      <geometry>
        <mesh filename="package://robotnik_powerball_description/meshes/powerball0.stl"/>
      </geometry>
      <material name="Grey"/>
    </visual>
    <collision>
      <origin rpy="0 0 0" xyz="0 0 0"/>
      <geometry>
        <mesh filename="package://robotnik_powerball_description/meshes/powerball0.stl"/>
      </geometry>
    </collision>
  </link>
  <joint name="${name}_1_joint" type="revolute">
    <origin rpy="0 0 0" xyz="0 0 -0.0897"/>
    <parent link="${name}_0_link"/>
    <child link="${name}_1_link"/>
    <axis xyz="0 0 -1"/>
    <!--axis xyz="0 0 1"/-->
    <calibration rising="0"/>
    <dynamics damping="10"/>
    <limit effort="370" lower="-2.97" upper="2.97" velocity="2.0"/>
    <safety_controller k_position="20" k_velocity="50" soft_lower_limit="-6.2731853" soft_upper_limit="6.2731853"/>
  </joint>
  <link name="${name}_1_link">
    <inertial>
      <origin rpy="0 0 0" xyz="0 0 0"/>
      <mass value="0.29364"/>
      <inertia ixx="0.01" ixy="0" ixz="0" iyy="0.01" iyz="0" izz="0.01"/>
    </inertial>
    <visual>
      <origin rpy="0 0 0" xyz="0 0 0"/>
      <geometry>
        <mesh filename="package://robotnik_powerball_description/meshes/powerball1.stl"/>
      </geometry>
      <material name="Blue"/>
    </visual>
    <collision>
      <origin rpy="0 0 0" xyz="0 0 0"/>
      <geometry>
        <mesh filename="package://robotnik_powerball_description/meshes/powerball1.stl"/>
      </geometry>
    </collision>
  </link>
  <joint name="${name}_2_joint" type="revolute">
    <origin rpy="1.5708 0 0" xyz="0 0 0"/>
    <parent link="${name}_1_link"/>
    <child link="${name}_2_link"/>
    <axis xyz="0 0 -1"/>
    <calibration rising="0"/>
    <dynamics damping="10"/>
    <limit effort="370" lower="-1.92" upper="1.92" velocity="2.0"/>
    <safety_controller k_position="20" k_velocity="50" soft_lower_limit="-2.0843" soft_upper_limit="2.0843"/>
  </joint>
  <link name="${name}_2_link">
    <inertial>
      <origin rpy="0 0 0" xyz="0 0 0"/>
      <mass value="1.68311"/>
      <inertia ixx="0.03" ixy="0" ixz="0" iyy="0.03" iyz="0" izz="0.03"/>
    </inertial>
    <visual>
      <origin rpy="0 0 0" xyz="0 0 0"/>
      <geometry>
        <mesh filename="package://robotnik_powerball_description/meshes/powerball2.stl"/>
      </geometry>
      <material name="Grey"/>
    </visual>
    <collision>
      <origin rpy="0 0 0" xyz="0 0 0"/>
      <geometry>
        <mesh filename="package://robotnik_powerball_description/meshes/powerball2.stl"/>
      </geometry>
    </collision>
  </link>
  <joint name="${name}_3_joint" type="revolute">
    <origin rpy="3.14159 0 0" xyz="0 -0.350 0"/>
    <parent link="${name}_2_link"/>
    <child link="${name}_3_link"/>
    <axis xyz="0 0 -1"/>
    <calibration rising="0"/>
    <dynamics damping="5"/>
    <limit effort="176" lower="-2.71" upper="2.71" velocity="2.0"/>
    <safety_controller k_position="20" k_velocity="25" soft_lower_limit="-6.2731853" soft_upper_limit="6.2731853"/>
  </joint>
  <link name="${name}_3_link">
    <inertial>
      <origin rpy="0 0 0" xyz="0 0 0"/>
      <mass value="2.1"/>
      <inertia ixx="0.03" ixy="0" ixz="0" iyy="0.03" iyz="0" izz="0.03"/>
    </inertial>
    <visual>
      <origin rpy="0 0 0" xyz="0 0 0"/>
      <geometry>
        <mesh filename="package://robotnik_powerball_description/meshes/powerball3.stl"/>
      </geometry>
      <material name="Blue"/>
    </visual>
    <collision>
      <origin rpy="0 0 0" xyz="0 0 0"/>
      <geometry>
        <mesh filename="package://robotnik_powerball_description/meshes/powerball3.stl"/>
      </geometry>
    </collision>
  </link>
  <joint name="${name}_4_joint" type="revolute">
    <origin rpy="1.5708 3.14159 0" xyz="0 0 0"/>
    <parent link="${name}_3_link"/>
    <child link="${name}_4_link"/>
    <axis xyz="0 0 1"/>
    <calibration rising="0"/>
    <dynamics damping="5"/>
    <limit effort="176" lower="-2.97" upper="2.97" velocity="2.0"/>
    <safety_controller k_position="20" k_velocity="25" soft_lower_limit="-2.0843951" soft_upper_limit="2.0843951"/>
  </joint>
  <link name="${name}_4_link">
    <inertial>
      <origin rpy="0 0 0" xyz="0 0 0"/>
      <mass value="1.68311"/>
      <inertia ixx="0.03" ixy="0" ixz="0" iyy="0.03" iyz="0" izz="0.03"/>
    </inertial>
    <visual>
      <origin rpy="0 0 0" xyz="0 0 0"/>
      <geometry>
        <mesh filename="package://robotnik_powerball_description/meshes/powerball4.stl"/>
      </geometry>
      <material name="Grey"/>
    </visual>
    <collision>
      <origin rpy="0 0 0" xyz="0 0 0"/>
      <geometry>
        <mesh filename="package://robotnik_powerball_description/meshes/powerball4.stl"/>
      </geometry>
    </collision>
  </link>
  <joint name="${name}_5_joint" type="revolute">
    <origin rpy="1.5708 0 0" xyz="0 0.005 -0.3049"/>
    <parent link="${name}_4_link"/>
    <child link="${name}_5_link"/>
    <axis xyz="0 0 -1"/>
    <calibration rising="0"/>
    <dynamics damping="5"/>
    <limit effort="41.6" lower="-2.44" upper="2.44" velocity="2.0"/>
    <safety_controller k_position="20" k_velocity="25" soft_lower_limit="-6.2731853" soft_upper_limit="6.2731853"/>
  </joint>
  <link name="${name}_5_link">
    <inertial>
      <origin rpy="0 0 0" xyz="0 0 0"/>
      <mass value="0.807"/>
      <inertia ixx="0.03" ixy="0" ixz="0" iyy="0.03" iyz="0" izz="0.03"/>
    </inertial>
    <visual>
      <origin rpy="0 0 0" xyz="0 0 0"/>
      <geometry>
        <mesh filename="package://robotnik_powerball_description/meshes/powerball5.stl"/>
      </geometry>
      <material name="Blue"/>
    </visual>
    <collision>
      <origin rpy="0 0 0" xyz="0 0 0"/>
      <geometry>
        <mesh filename="package://robotnik_powerball_description/meshes/powerball5.stl"/>
      </geometry>
    </collision>
  </link>
  <joint name="${name}_6_joint" type="revolute">
    <origin rpy="-1.5708 0 0" xyz="0 0 0"/>
    <parent link="${name}_5_link"/>
    <child link="${name}_6_link"/>
    <axis xyz="0 0 -1"/>
    <calibration rising="0"/>
    <dynamics damping="5"/>
    <limit effort="20.1" lower="-2.97" upper="2.97" velocity="2.0"/>
    <safety_controller k_position="20" k_velocity="25" soft_lower_limit="-2.0843951" soft_upper_limit="2.0843951"/>
  </joint>
  <link name="${name}_6_link">
    <inertial>
      <origin rpy="0 0 0" xyz="0 0 0"/>
      <mass value="0.819"/>
      <inertia ixx="0.01" ixy="0" ixz="0" iyy="0.01" iyz="0" izz="0.01"/>
    </inertial>
    <visual>
      <origin rpy="0 0 0" xyz="0 0 0"/>
      <geometry>
        <mesh filename="package://robotnik_powerball_description/meshes/powerball6.stl"/>
      </geometry>
      <material name="Grey"/>
    </visual>
    <collision>
      <origin rpy="0 0 0" xyz="0 0 0"/>
      <geometry>
        <mesh filename="package://robotnik_powerball_description/meshes/powerball6.stl"/>
      </geometry>
    </collision>
  </link>
  <gazebo reference="${name}_0_link">
    <material value="PR2/Grey"/>
    <turnGravityOff>false</turnGravityOff>
    <selfCollide>true</selfCollide>
  </gazebo>
  <gazebo reference="${name}_1_link">
    <material value="PR2/Blue"/>
    <turnGravityOff>false</turnGravityOff>
    <selfCollide>true</selfCollide>
  </gazebo>
  <gazebo reference="${name}_2_link">
    <material value="PR2/Grey"/>
    <turnGravityOff>false</turnGravityOff>
    <selfCollide>true</selfCollide>
  </gazebo>
  <gazebo reference="${name}_3_link">
    <material value="PR2/Blue"/>
    <turnGravityOff>false</turnGravityOff>
    <selfCollide>true</selfCollide>
  </gazebo>
  <gazebo reference="${name}_4_link">
    <material value="PR2/Grey"/>
    <turnGravityOff>false</turnGravityOff>
    <selfCollide>true</selfCollide>
  </gazebo>
  <gazebo reference="${name}_5_link">
    <material value="PR2/Blue"/>
    <turnGravityOff>false</turnGravityOff>
    <selfCollide>true</selfCollide>
  </gazebo>
  <gazebo reference="${name}_6_link">
    <material value="PR2/Grey"/>
    <turnGravityOff>false</turnGravityOff>
    <selfCollide>true</selfCollide>
  </gazebo>
  <transmission name="arm_1_trans" type="pr2_mechanism_model/SimpleTransmission">
    <actuator name="arm_1_motor"/>
    <joint name="${name}_1_joint"/>
    <mechanicalReduction>1</mechanicalReduction>
  </transmission>
  <transmission name="arm_2_trans" type="pr2_mechanism_model/SimpleTransmission">
    <actuator name="arm_2_motor"/>
    <joint name="${name}_2_joint"/>
    <mechanicalReduction>1</mechanicalReduction>
  </transmission>
  <transmission name="arm_3_trans" type="pr2_mechanism_model/SimpleTransmission">
    <actuator name="arm_3_motor"/>
    <joint name="${name}_3_joint"/>
    <mechanicalReduction>1</mechanicalReduction>
  </transmission>
  <transmission name="arm_4_trans" type="pr2_mechanism_model/SimpleTransmission">
    <actuator name="arm_4_motor"/>
    <joint name="${name}_4_joint"/>
    <mechanicalReduction>1</mechanicalReduction>
  </transmission>
  <transmission name="arm_5_trans" type="pr2_mechanism_model/SimpleTransmission">
    <actuator name="arm_5_motor"/>
    <joint name="${name}_5_joint"/>
    <mechanicalReduction>1</mechanicalReduction>
  </transmission>
  <transmission name="arm_6_trans" type="pr2_mechanism_model/SimpleTransmission">
    <actuator name="arm_6_motor"/>
    <joint name="${name}_6_joint"/>
    <mechanicalReduction>1</mechanicalReduction>
  </transmission>

  
  <!-- GRIPPER -->
  
    <xacro:wsg_50_xacro name="wsg_50_powerball" parent="${name}_6_link">
    		<origin xyz="0 0 -0.085" rpy="3.1415 0 1.57" />
  	</xacro:wsg_50_xacro>

  </xacro:macro>

</robot>
